<?xml version="1.0"?>
<robot name="myfirst">
  <link name="base_link">
    <visual>
      <geometry>
					<mesh filename="package://uvicbot_description/meshes/uvicbot_body.stl" scale="0.001 0.001 0.001"/>
			</geometry>
      <material name="White">
        <color rgba="1.0 1.0 1.0 1.0"/>
      </material>
      <origin xyz="0 0 0" rpy="0 0 0" />
    </visual>
  </link>
  <link name="head_link">
    <visual>
      <geometry>
        <mesh filename="package://uvicbot_description/meshes/uvicbot_head.stl" scale="0.001 0.001 0.001"/>
      </geometry>
      <material name="Blue">
        <color rgba="0.1 0.1 0.5 1.0"/>
      </material>
      <origin xyz="0 0 0.084" rpy="0 0 0" />
    </visual>
  </link>
  <link name="camera">
    <visual>
      <geometry>
        <cylinder length="0.001" radius="0.001"/>
      </geometry>
      <origin xyz="0 0 0" rpy="1.57075 0 1.57075" />
    </visual>
  </link>
  <joint name="servo_joint" type="revolute">
    <origin xyz="-0.01 0 0" rpy="0 0 0"/>
    <parent link="base_link"/>
    <child link="head_link"/>
    <axis xyz="0 0 1" />
    <limit lower="-1.57075" upper="1.57075" effort="1" velocity="1" />
  </joint>
  <joint name="camera_joint" type="fixed">
    <origin xyz="0.05 0 0.1235" rpy="0 0 0"/>
    <parent link="head_link"/>
    <child link="camera"/>
 </joint>
</robot>
